Workbook
Name ExternalData_1: 'JKRQuery (2)'!$A$1:$D$169
Name Slicer_State1: #N/A

Sheet Overall Loss >

Sheet Link
A1: No | B1: Link | C1: Description
A2: 1 | B2: https://www.worldbank.org/en/country/malaysia/publication/flood-risk-management-leveraging-finance-for-business-resilience-in-malaysia | C2: Managing Flood Risks- Leveraging Finance for Business Resilience in Malaysia
A3: =A2+1 -> 2 | B3: https://www.unescap.org/sites/default/d8files/event-documents/02%20MYS%203.%2022nd%20meeting%20twg%20of%20disaster%20stats_%20Malaysia.pdf | C3: IMPACT OF FLOODS IN MALAYSIA 2022: MALAYSIA’S EXPERIENCE
A4: =A3+1 -> 3 | B4: https://www.dosm.gov.my/portal-main/release-content/special-report-on-impact-of-floods-in-malaysia-2021 | C4: Flood Impact Archive DOSM
A5: =A4+1 -> 4 | B5: https://reliefweb.int/disaster/fl-2021-000209-mys | C5: Flash Flood Dec 2021
A6: =A5+1 -> 5 | B6: https://www.met.gov.my/penerbitan/laporan-tahunan/ | C6: Annual Report by METMalaysia
A7: =A6+1 -> 6 | B7: https://www.water.gov.my/index.php/pages/view/2113?mid=691 | C7: Department of Irrigation and Drainage
A8: =A7+1 -> 7 | B8: https://publicinfobanjir.water.gov.my/hujan/data-hujan/?lang=en | C8: Rainfall Data - Department of Irrigation and Drainage Malaysia
A9: =A8+1 -> 8 | B9: https://www.ukm.my/jkukm/wp-content/uploads/2025/3702/28.pdf | C9: A Review of Major Flood Events in Malaysia Between 1970-2024
A10: =A9+1 -> 9 | B10: https://www.iseas.edu.sg/articles-commentaries/iseas-perspective/2022-26-malaysias-floods-of-december-2021-can-future-disasters-be-avoided-by-serina-rahman/ | C10: “Malaysia’s Floods of December 2021: Can Future Disasters be Avoided?” by Serina Rahman

Sheet Malaysia
A3: Sum of Value | B3: Year | I3: KRI Name | J3: Value | K3: Status
A4: Category | B4: 2025 | C4: Grand Total | I4: National Flood Loss Growth Rate | J4: =GETPIVOTDATA("Sum of Value",$A$3, "Year", 2025)/GETPIVOTDATA("Sum of Value",$A$3, "Year", 2024)-1 -> #REF! | K4: =IF(J4>0.2,"🔴 Red",IF(J4>0,"🟡 Amber","🟢 Green")) -> #REF!
A5: Agriculture | B5: 52559.126 | C5: 52559.126 | I5: Residential Exposure Ratio | J5: =GETPIVOTDATA("Sum of Value",$A$3, "Year", 2025, "Categories", "Living Quarters")/GETPIVOTDATA("Sum of Value",$A$3, "Year", 2025) -> 0.28860366 | K5: =IF(J5>0.45,"🔴 Red",IF(J5>0.3,"🟡 Amber","🟢 Green")) -> 🟢 Green
A6: Business Premises | B6: 13448.684 | C6: 13448.684 | I6: Infrastructure Dependency Risk | J6: =GETPIVOTDATA("Sum of Value",$A$3, "Year", 2025, "Categories", "Infrastructure")/GETPIVOTDATA("Sum of Value",$A$3, "Year", 2025) -> 0.5969128 | K6: =IF(J6>0.45,"🔴 Red",IF(J6>0.3,"🟡 Amber","🟢 Green")) -> 🔴 Red
A7: Infrastructure | B7: 380181.72 | C7: 380181.72 | I7: State Concentration risk | J7: =GETPIVOTDATA("Sum of Loss",'Loss by State'!$A$3)/GETPIVOTDATA("Sum of Value",$A$3,"Year",2025) -> #REF! | K7: =IF(J7>0.45,"🔴 Red",IF(J7>0.3,"🟡 Amber","🟢 Green")) -> #REF!
A8: Living Quarters | B8: 183815.52 | C8: 183815.52
A9: Manufacturing | B9: 75.6 | C9: 75.6
A10: Vehicles | B10: 6832.6793 | C10: 6832.6793
A11: Grand Total | B11: 636913.32 | C11: 636913.32
A13: Main Contributer: | C13: =INDEX($A$5:$A$9, MATCH(MAX(C5:C9), C5:C9, 0)) -> Infrastructure | D13: =INDEX($A$5:$A$9, MATCH(MAX(D5:D9), D5:D9, 0)) -> #N/A | E13: =INDEX($A$5:$A$9, MATCH(MAX(E5:E9), E5:E9, 0)) -> #N/A | F13: =INDEX($A$5:$A$9, MATCH(MAX(F5:F9), F5:F9, 0)) -> #N/A
A15: Sum of Value | B15: Year
A16: Category | B16: 2021 | C16: 2022 | D16: 2023 | E16: 2024 | F16: 2025
A17: Agriculture | C17: 0.70546879 | D17: -0.21930553 | E17: 0.53546186 | F17: -0.71623683
A18: Business Premises | C18: -0.90432529 | D18: 0.057548445 | E18: 0.016209678 | F18: -0.75122414
A19: Infrastructure | C19: -0.68161629 | D19: -0.40207061 | E19: -0.20318829 | F19: 0.25315499
A20: Living Quarters | C20: -0.90296115 | D20: 0.069034298 | E20: 1.2122655 | F20: -0.50617996
A21: Manufacturing | C21: -0.99023224 | D21: 0.17837143 | E21: -0.88663391 | F21: -0.93500079
A22: Vehicles | C22: -0.98086977 | D22: 0.18755671 | E22: -0.22522787 | F22: -0.60500744
A23: Grand Total | C23: -0.83206658 | D23: -0.26407789 | E23: 0.23555438 | F23: -0.31760799
A26: Sum of Value | B26: Year
A27: Category | B27: 2021 | C27: 2022 | D27: 2023 | E27: 2024 | F27: 2025
A28: Agriculture | C28: 63915.472 | D28: -33886.097 | E28: 64592.429 | F28: -132662.68
A29: Business Premises | C29: -475461.63 | D29: 2894.82 | E29: 862.30843 | F29: -40610.758
A30: Infrastructure | C30: -1363232.6 | D30: -256025.46 | E30: -77362.307 | F30: 76802.071
A31: Living Quarters | C31: -1464562.8 | D31: 10865.495 | E31: 203973.6 | F31: -188416.27
A32: Manufacturing | C32: -882653.43 | D32: 1553.0078 | E32: -9096.5114 | F32: -1087.491
A33: Vehicles | C33: -963973.03 | D33: 3526.1954 | E33: -5028.6368 | F33: -10465.569
A34: Grand Total | C34: -5085968 | D34: -271072.04 | E34: 177940.88 | F34: -296440.7
A36: Main Contributer: | C36: =INDEX($A$28:$A$33, MATCH(MAX(C28:C33), C28:C33, 0)) -> Agriculture | D36: =INDEX($A$28:$A$33, MATCH(MAX(D28:D33), D28:D33, 0)) -> Living Quarters | E36: =INDEX($A$28:$A$33, MATCH(MAX(E28:E33), E28:E33, 0)) -> Living Quarters | F36: =INDEX($A$28:$A$33, MATCH(MAX(F28:F33), F28:F33, 0)) -> Infrastructure

Sheet Sub Category >

Sheet State Analysis

Sheet Loss by Category
A2: State | B2: (All)
A4: Sum of Loss | B4: Year | I4: Highest Losses per Year | J4: Category
A5: Category | B5: 2021 | C5: 2022 | D5: 2023 | E5: 2024 | F5: 2025 | G5: Grand Total | I5: 2022 | J5: =INDEX($A$6:$A$11, MATCH(MAX(B6:B11), B6:B11, 0)) -> Living Quarter
A6: Agriculture | B6: 0 | C6: 154515.47 | D6: 120629.37 | E6: 185221.8 | F6: 52559.126 | G6: 512925.78 | I6: 2023 | J6: =INDEX($A$6:$A$11, MATCH(MAX(C6:C11), C6:C11, 0)) -> Infrastructure
A7: Infrastructure | B7: 0 | C7: 632878.07 | D7: 376498.36 | E7: 300382.48 | F7: 376648.96 | G7: 1686407.9 | I7: 2024 | J7: =INDEX($A$6:$A$11, MATCH(MAX(E6:E11), E6:E11, 0)) -> Living Quarter
A8: Manufacturing | B8: 891360.03 | C8: 8706.5947 | D8: 10259.602 | E8: 1163.091 | F8: 75.6 | G8: 911564.92 | I8: 2025 | J8: =INDEX($A$6:$A$11, MATCH(MAX(F6:F11), F6:F11, 0)) -> Infrastructure
A9: Premises | B9: 525763.94 | C9: 50302.314 | D9: 53197.134 | E9: 54059.442 | F9: 13448.684 | G9: 696771.52 | I9: Overall | J9: =INDEX($A$6:$A$11, MATCH(MAX(G6:G11), G6:G11, 0)) -> Living Quarter
A10: Vehicle | B10: 982773.72 | C10: 18800.689 | D10: 22326.885 | E10: 17298.248 | F10: 6832.6793 | G10: 1048032.2
A11: Living Quarter | B11: 1621955.5 | C11: 157392.7 | D11: 168258.19 | E11: 372231.79 | F11: 183815.52 | G11: 2503653.7
A12: Grand Total | B12: 4021853.2 | C12: 1022595.8 | D12: 751169.55 | E12: 930356.86 | F12: 633380.56 | G12: 7359356

Sheet Loss by State
A1: Top 5 States with the Highest Loss

Sheet Agriculture by State >

Sheet AgriculturePivot
A1: Category | B1: (All)
A3: Sum of Value | B3: Year
A4: State | B4: 2022 | C4: 2023 | D4: 2024 | E4: 2025 | F4: Grand Total
A5: Johor | B5: 247.36 | C5: 25238.669 | D5: 2432.7901 | E5: 13010.384 | F5: 40929.203
A6: Kedah | B6: 327.1 | C6: 416.2 | D6: 118210.03 | E6: 5039.94 | F6: 123993.27
A7: Kelantan | B7: 66034.69 | C7: 52547.492 | D7: 43788.086 | E7: 4383.692 | F7: 166753.96
A8: Melaka | B8: 98.3 | C8: 207.7424 | D8: 471.6866 | E8: 512.298 | F8: 1290.027
A9: Negeri Sembilan | B9: 3007.138 | C9: 3023.638 | D9: 1209.919 | E9: 2623.4052 | F9: 9864.1002
A10: Pahang | B10: 1692.82 | C10: 3369.42 | D10: 8807.069 | E10: 4288.7644 | F10: 18158.073
A11: Perak | B11: 767.813 | C11: 767.813 | D11: 312.341 | E11: 4479.075 | F11: 6327.042
A12: Perlis | B12: 0 | C12: 0 | D12: 176.15 | E12: 1221.972 | F12: 1398.122
A13: Pulau Pinang | B13: 74.848 | C13: 99.848 | D13: 63 | E13: 2592.7346 | F13: 2830.4306
A14: Sabah | B14: 0 | C14: 195.75 | D14: 683.627 | E14: 3648.822 | F14: 4528.199
A15: Sarawak | B15: 98.5 | C15: 196.78 | D15: 518.406 | E15: 163 | F15: 976.686
A16: Selangor | B16: 3144.604 | C16: 3284.383 | D16: 1887.4807 | E16: 9582.0305 | F16: 17898.498
... A18: Grand Total | B18: 154515.47 | C18: 120629.37 | D18: 185221.8 | E18: 52558.478 | F18: 512925.13

Sheet AgriSubCatPivot
A1: Category | B1: (All)
A3: Sum of Value | B3: Column Labels
A4: State | B4: 2022 | C4: 2023 | D4: 2024 | E4: 2025 | F4: Grand Total
A5: Johor | B5: 247.36 | C5: 1 | D5: 2429.715 | E5: 13010.384 | F5: 15688.459
A6: Kedah | B6: 327.1 | C6: 1 | D6: 118210.03 | E6: 5039.94 | F6: 123578.07
A7: Kelantan | B7: 66034.69 | C7: 1 | D7: 22443.98 | E7: 4383.692 | F7: 92863.362
A8: Melaka | B8: 98.3 | C8: 1 | D8: 471.6866 | E8: 512.298 | F8: 1083.2846
A9: Negeri Sembilan | B9: 3007.138 | C9: 1 | D9: 1209.919 | E9: 2623.4052 | F9: 6841.4622
A10: Pahang | B10: 1692.82 | C10: 1 | D10: 8807.069 | E10: 4288.7644 | F10: 14789.653
A11: Perak | B11: 767.813 | C11: 1 | D11: 312.341 | E11: 4479.075 | F11: 5560.229
A12: Perlis | B12: 0 | C12: 1 | D12: 176.15 | E12: 1221.972 | F12: 1399.122
A13: Pulau Pinang | B13: 74.848 | C13: 1 | D13: 63 | E13: 2592.7346 | F13: 2731.5826
A14: Sabah | B14: 0 | C14: 1 | D14: 44.377 | E14: 3646.322 | F14: 3691.699
A15: Sarawak | B15: 98.5 | C15: 1 | D15: 453.222 | E15: 94 | F15: 646.722
A16: Selangor | B16: 3144.604 | C16: 1 | D16: 1870.158 | E16: 9582.0305 | F16: 14597.792
... A19: Grand Total | B19: 154515.47 | C19: 14 | D19: 162623.78 | E19: 52486.978 | F19: 369640.23

Sheet Agriculture by State
A1: h | B1: Agriculture and Food Security (RM '000) | G1: Movement | L1: % YoY
A2: Year | B2: 2022 | C2: 2023 | D2: 2024 | E2: 2025 | G2: 2022 | H2: 2023 | I2: 2024 | J2: 2025 | L2: 2022 | M2: 2023 | N2: 2024 | O2: 2025
A3: Malaysia | B3: 154515.47 | C3: 119504.67 | D3: 162623.78 | E3: 52486.978 | G3: - | H3: =Agriculture_FoodSecurity[[#This Row],[2023]]-Agriculture_FoodSecurity[[#This Row],[2022]] -> -35010.798 | I3: =Agriculture_FoodSecurity[[#This Row],[2024]]-Agriculture_FoodSecurity[[#This Row],[2023]] -> 43119.109 | J3: =Agriculture_FoodSecurity[[#This Row],[2025]]-Agriculture_FoodSecurity[[#This Row],[2024]] -> -110136.81 | L3: - | M3: =IF(OR(Agriculture_FoodSecurity[[#This Row],[2022]]="n.a", Agriculture_FoodSecurity[[#This Row],[2022]]=0, Agriculture_FoodSecurity[[#This Row],[2023]]="n.a"), "-",H3/Agriculture_FoodSecurity[[#This Row],[2022]]) -> -0.22658441 | N3: =IF(OR(Agriculture_FoodSecurity[[#This Row],[2023]]="n.a", Agriculture_FoodSecurity[[#This Row],[2023]]=0, Agriculture_FoodSecurity[[#This Row],[2024]]="n.a"), "-",I3/Agriculture_FoodSecurity[[#This Row],[2023]]) -> 0.36081525 | O3: =IF(OR(Agriculture_FoodSecurity[[#This Row],[2024]]="n.a", Agriculture_FoodSecurity[[#This Row],[2024]]=0, Agriculture_FoodSecurity[[#This Row],[2025]]="n.a"), "-",J3/Agriculture_FoodSecurity[[#This Row],[2024]]) -> -0.67724907
A4: Johor | B4: 247.36 | C4: 25196.239 | D4: 2429.715 | E4: 13010.384 | G4: - | H4: =Agriculture_FoodSecurity[[#This Row],[2023]]-Agriculture_FoodSecurity[[#This Row],[2022]] -> 24948.879 | I4: =Agriculture_FoodSecurity[[#This Row],[2024]]-Agriculture_FoodSecurity[[#This Row],[2023]] -> -22766.524 | J4: =Agriculture_FoodSecurity[[#This Row],[2025]]-Agriculture_FoodSecurity[[#This Row],[2024]] -> 10580.669 | L4: - | M4: =IF(OR(Agriculture_FoodSecurity[[#This Row],[2022]]="n.a", Agriculture_FoodSecurity[[#This Row],[2022]]=0, Agriculture_FoodSecurity[[#This Row],[2023]]="n.a"), "-",H4/Agriculture_FoodSecurity[[#This Row],[2022]]) -> 100.8606 | N4: =IF(OR(Agriculture_FoodSecurity[[#This Row],[2023]]="n.a", Agriculture_FoodSecurity[[#This Row],[2023]]=0, Agriculture_FoodSecurity[[#This Row],[2024]]="n.a"), "-",I4/Agriculture_FoodSecurity[[#This Row],[2023]]) -> -0.90356835 | O4: =IF(OR(Agriculture_FoodSecurity[[#This Row],[2024]]="n.a", Agriculture_FoodSecurity[[#This Row],[2024]]=0, Agriculture_FoodSecurity[[#This Row],[2025]]="n.a"), "-",J4/Agriculture_FoodSecurity[[#This Row],[2024]]) -> 4.3546955
A5: Kedah | B5: 327.1 | C5: 416.2 | D5: 118210.03 | E5: 5039.94 | G5: - | H5: =Agriculture_FoodSecurity[[#This Row],[2023]]-Agriculture_FoodSecurity[[#This Row],[2022]] -> 89.1 | I5: =Agriculture_FoodSecurity[[#This Row],[2024]]-Agriculture_FoodSecurity[[#This Row],[2023]] -> 117793.83 | J5: =Agriculture_FoodSecurity[[#This Row],[2025]]-Agriculture_FoodSecurity[[#This Row],[2024]] -> -113170.09 | L5: - | M5: =IF(OR(Agriculture_FoodSecurity[[#This Row],[2022]]="n.a", Agriculture_FoodSecurity[[#This Row],[2022]]=0, Agriculture_FoodSecurity[[#This Row],[2023]]="n.a"), "-",H5/Agriculture_FoodSecurity[[#This Row],[2022]]) -> 0.27239376 | N5: =IF(OR(Agriculture_FoodSecurity[[#This Row],[2023]]="n.a", Agriculture_FoodSecurity[[#This Row],[2023]]=0, Agriculture_FoodSecurity[[#This Row],[2024]]="n.a"), "-",I5/Agriculture_FoodSecurity[[#This Row],[2023]]) -> 283.02218 | O5: =IF(OR(Agriculture_FoodSecurity[[#This Row],[2024]]="n.a", Agriculture_FoodSecurity[[#This Row],[2024]]=0, Agriculture_FoodSecurity[[#This Row],[2025]]="n.a"), "-",J5/Agriculture_FoodSecurity[[#This Row],[2024]]) -> -0.95736453
A6: Kelantan | B6: 66034.69 | C6: 52525.092 | D6: 22443.98 | E6: 4383.692 | G6: - | H6: =Agriculture_FoodSecurity[[#This Row],[2023]]-Agriculture_FoodSecurity[[#This Row],[2022]] -> -13509.598 | I6: =Agriculture_FoodSecurity[[#This Row],[2024]]-Agriculture_FoodSecurity[[#This Row],[2023]] -> -30081.113 | J6: =Agriculture_FoodSecurity[[#This Row],[2025]]-Agriculture_FoodSecurity[[#This Row],[2024]] -> -18060.288 | L6: - | M6: =IF(OR(Agriculture_FoodSecurity[[#This Row],[2022]]="n.a", Agriculture_FoodSecurity[[#This Row],[2022]]=0, Agriculture_FoodSecurity[[#This Row],[2023]]="n.a"), "-",H6/Agriculture_FoodSecurity[[#This Row],[2022]]) -> -0.20458335 | N6: =IF(OR(Agriculture_FoodSecurity[[#This Row],[2023]]="n.a", Agriculture_FoodSecurity[[#This Row],[2023]]=0, Agriculture_FoodSecurity[[#This Row],[2024]]="n.a"), "-",I6/Agriculture_FoodSecurity[[#This Row],[2023]]) -> -0.57269986 | O6: =IF(OR(Agriculture_FoodSecurity[[#This Row],[2024]]="n.a", Agriculture_FoodSecurity[[#This Row],[2024]]=0, Agriculture_FoodSecurity[[#This Row],[2025]]="n.a"), "-",J6/Agriculture_FoodSecurity[[#This Row],[2024]]) -> -0.80468294
A7: Melaka | B7: 98.3 | C7: 206.4424 | D7: 471.6866 | E7: 512.298 | G7: - | H7: =Agriculture_FoodSecurity[[#This Row],[2023]]-Agriculture_FoodSecurity[[#This Row],[2022]] -> 108.1424 | I7: =Agriculture_FoodSecurity[[#This Row],[2024]]-Agriculture_FoodSecurity[[#This Row],[2023]] -> 265.2442 | J7: =Agriculture_FoodSecurity[[#This Row],[2025]]-Agriculture_FoodSecurity[[#This Row],[2024]] -> 40.6114 | L7: - | M7: =IF(OR(Agriculture_FoodSecurity[[#This Row],[2022]]="n.a", Agriculture_FoodSecurity[[#This Row],[2022]]=0, Agriculture_FoodSecurity[[#This Row],[2023]]="n.a"), "-",H7/Agriculture_FoodSecurity[[#This Row],[2022]]) -> 1.1001261 | N7: =IF(OR(Agriculture_FoodSecurity[[#This Row],[2023]]="n.a", Agriculture_FoodSecurity[[#This Row],[2023]]=0, Agriculture_FoodSecurity[[#This Row],[2024]]="n.a"), "-",I7/Agriculture_FoodSecurity[[#This Row],[2023]]) -> 1.2848339 | O7: =IF(OR(Agriculture_FoodSecurity[[#This Row],[2024]]="n.a", Agriculture_FoodSecurity[[#This Row],[2024]]=0, Agriculture_FoodSecurity[[#This Row],[2025]]="n.a"), "-",J7/Agriculture_FoodSecurity[[#This Row],[2024]]) -> 0.086098269
A8: Negeri Sembilan | B8: 3007.138 | C8: 3023.638 | D8: 1209.919 | E8: 2623.4052 | G8: - | H8: =Agriculture_FoodSecurity[[#This Row],[2023]]-Agriculture_FoodSecurity[[#This Row],[2022]] -> 16.5 | I8: =Agriculture_FoodSecurity[[#This Row],[2024]]-Agriculture_FoodSecurity[[#This Row],[2023]] -> -1813.719 | J8: =Agriculture_FoodSecurity[[#This Row],[2025]]-Agriculture_FoodSecurity[[#This Row],[2024]] -> 1413.4862 | L8: - | M8: =IF(OR(Agriculture_FoodSecurity[[#This Row],[2022]]="n.a", Agriculture_FoodSecurity[[#This Row],[2022]]=0, Agriculture_FoodSecurity[[#This Row],[2023]]="n.a"), "-",H8/Agriculture_FoodSecurity[[#This Row],[2022]]) -> 0.0054869447 | N8: =IF(OR(Agriculture_FoodSecurity[[#This Row],[2023]]="n.a", Agriculture_FoodSecurity[[#This Row],[2023]]=0, Agriculture_FoodSecurity[[#This Row],[2024]]="n.a"), "-",I8/Agriculture_FoodSecurity[[#This Row],[2023]]) -> -0.59984661 | O8: =IF(OR(Agriculture_FoodSecurity[[#This Row],[2024]]="n.a", Agriculture_FoodSecurity[[#This Row],[2024]]=0, Agriculture_FoodSecurity[[#This Row],[2025]]="n.a"), "-",J8/Agriculture_FoodSecurity[[#This Row],[2024]]) -> 1.1682486
A9: Pahang | B9: 1692.82 | C9: 2694.02 | D9: 8807.069 | E9: 4288.7644 | G9: - | H9: =Agriculture_FoodSecurity[[#This Row],[2023]]-Agriculture_FoodSecurity[[#This Row],[2022]] -> 1001.2 | I9: =Agriculture_FoodSecurity[[#This Row],[2024]]-Agriculture_FoodSecurity[[#This Row],[2023]] -> 6113.049 | J9: =Agriculture_FoodSecurity[[#This Row],[2025]]-Agriculture_FoodSecurity[[#This Row],[2024]] -> -4518.3046 | L9: - | M9: =IF(OR(Agriculture_FoodSecurity[[#This Row],[2022]]="n.a", Agriculture_FoodSecurity[[#This Row],[2022]]=0, Agriculture_FoodSecurity[[#This Row],[2023]]="n.a"), "-",H9/Agriculture_FoodSecurity[[#This Row],[2022]]) -> 0.59143914 | N9: =IF(OR(Agriculture_FoodSecurity[[#This Row],[2023]]="n.a", Agriculture_FoodSecurity[[#This Row],[2023]]=0, Agriculture_FoodSecurity[[#This Row],[2024]]="n.a"), "-",I9/Agriculture_FoodSecurity[[#This Row],[2023]]) -> 2.2691179 | O9: =IF(OR(Agriculture_FoodSecurity[[#This Row],[2024]]="n.a", Agriculture_FoodSecurity[[#This Row],[2024]]=0, Agriculture_FoodSecurity[[#This Row],[2025]]="n.a"), "-",J9/Agriculture_FoodSecurity[[#This Row],[2024]]) -> -0.51303159
A10: Pulau Pinang | B10: 74.848 | C10: 99.848 | D10: 63 | E10: 2592.7346 | G10: - | H10: =Agriculture_FoodSecurity[[#This Row],[2023]]-Agriculture_FoodSecurity[[#This Row],[2022]] -> 25 | I10: =Agriculture_FoodSecurity[[#This Row],[2024]]-Agriculture_FoodSecurity[[#This Row],[2023]] -> -36.848 | J10: =Agriculture_FoodSecurity[[#This Row],[2025]]-Agriculture_FoodSecurity[[#This Row],[2024]] -> 2529.7346 | L10: - | M10: =IF(OR(Agriculture_FoodSecurity[[#This Row],[2022]]="n.a", Agriculture_FoodSecurity[[#This Row],[2022]]=0, Agriculture_FoodSecurity[[#This Row],[2023]]="n.a"), "-",H10/Agriculture_FoodSecurity[[#This Row],[2022]]) -> 0.33401026 | N10: =IF(OR(Agriculture_FoodSecurity[[#This Row],[2023]]="n.a", Agriculture_FoodSecurity[[#This Row],[2023]]=0, Agriculture_FoodSecurity[[#This Row],[2024]]="n.a"), "-",I10/Agriculture_FoodSecurity[[#This Row],[2023]]) -> -0.36904094 | O10: =IF(OR(Agriculture_FoodSecurity[[#This Row],[2024]]="n.a", Agriculture_FoodSecurity[[#This Row],[2024]]=0, Agriculture_FoodSecurity[[#This Row],[2025]]="n.a"), "-",J10/Agriculture_FoodSecurity[[#This Row],[2024]]) -> 40.154517
A11: Perak | B11: 767.813 | C11: 767.813 | D11: 312.341 | E11: 4479.075 | G11: - | H11: =Agriculture_FoodSecurity[[#This Row],[2023]]-Agriculture_FoodSecurity[[#This Row],[2022]] -> 0 | I11: =Agriculture_FoodSecurity[[#This Row],[2024]]-Agriculture_FoodSecurity[[#This Row],[2023]] -> -455.472 | J11: =Agriculture_FoodSecurity[[#This Row],[2025]]-Agriculture_FoodSecurity[[#This Row],[2024]] -> 4166.734 | L11: - | M11: =IF(OR(Agriculture_FoodSecurity[[#This Row],[2022]]="n.a", Agriculture_FoodSecurity[[#This Row],[2022]]=0, Agriculture_FoodSecurity[[#This Row],[2023]]="n.a"), "-",H11/Agriculture_FoodSecurity[[#This Row],[2022]]) -> 0 | N11: =IF(OR(Agriculture_FoodSecurity[[#This Row],[2023]]="n.a", Agriculture_FoodSecurity[[#This Row],[2023]]=0, Agriculture_FoodSecurity[[#This Row],[2024]]="n.a"), "-",I11/Agriculture_FoodSecurity[[#This Row],[2023]]) -> -0.59320694 | O11: =IF(OR(Agriculture_FoodSecurity[[#This Row],[2024]]="n.a", Agriculture_FoodSecurity[[#This Row],[2024]]=0, Agriculture_FoodSecurity[[#This Row],[2025]]="n.a"), "-",J11/Agriculture_FoodSecurity[[#This Row],[2024]]) -> 13.340336
A12: Perlis | B12: 0 | C12: 0 | D12: 176.15 | E12: 1221.972 | G12: - | H12: =Agriculture_FoodSecurity[[#This Row],[2023]]-Agriculture_FoodSecurity[[#This Row],[2022]] -> 0 | I12: =Agriculture_FoodSecurity[[#This Row],[2024]]-Agriculture_FoodSecurity[[#This Row],[2023]] -> 176.15 | J12: =Agriculture_FoodSecurity[[#This Row],[2025]]-Agriculture_FoodSecurity[[#This Row],[2024]] -> 1045.822 | L12: - | M12: =IF(OR(Agriculture_FoodSecurity[[#This Row],[2022]]="n.a", Agriculture_FoodSecurity[[#This Row],[2022]]=0, Agriculture_FoodSecurity[[#This Row],[2023]]="n.a"), "-",H12/Agriculture_FoodSecurity[[#This Row],[2022]]) -> - | N12: =IF(OR(Agriculture_FoodSecurity[[#This Row],[2023]]="n.a", Agriculture_FoodSecurity[[#This Row],[2023]]=0, Agriculture_FoodSecurity[[#This Row],[2024]]="n.a"), "-",I12/Agriculture_FoodSecurity[[#This Row],[2023]]) -> - | O12: =IF(OR(Agriculture_FoodSecurity[[#This Row],[2024]]="n.a", Agriculture_FoodSecurity[[#This Row],[2024]]=0, Agriculture_FoodSecurity[[#This Row],[2025]]="n.a"), "-",J12/Agriculture_FoodSecurity[[#This Row],[2024]]) -> 5.9371104
A13: Selangor | B13: 3144.604 | C13: 3284.383 | D13: 1870.158 | E13: 9582.0305 | G13: - | H13: =Agriculture_FoodSecurity[[#This Row],[2023]]-Agriculture_FoodSecurity[[#This Row],[2022]] -> 139.779 | I13: =Agriculture_FoodSecurity[[#This Row],[2024]]-Agriculture_FoodSecurity[[#This Row],[2023]] -> -1414.225 | J13: =Agriculture_FoodSecurity[[#This Row],[2025]]-Agriculture_FoodSecurity[[#This Row],[2024]] -> 7711.8725 | L13: - | M13: =IF(OR(Agriculture_FoodSecurity[[#This Row],[2022]]="n.a", Agriculture_FoodSecurity[[#This Row],[2022]]=0, Agriculture_FoodSecurity[[#This Row],[2023]]="n.a"), "-",H13/Agriculture_FoodSecurity[[#This Row],[2022]]) -> 0.04445043 | N13: =IF(OR(Agriculture_FoodSecurity[[#This Row],[2023]]="n.a", Agriculture_FoodSecurity[[#This Row],[2023]]=0, Agriculture_FoodSecurity[[#This Row],[2024]]="n.a"), "-",I13/Agriculture_FoodSecurity[[#This Row],[2023]]) -> -0.43059077 | O13: =IF(OR(Agriculture_FoodSecurity[[#This Row],[2024]]="n.a", Agriculture_FoodSecurity[[#This Row],[2024]]=0, Agriculture_FoodSecurity[[#This Row],[2025]]="n.a"), "-",J13/Agriculture_FoodSecurity[[#This Row],[2024]]) -> 4.1236476
A14: Terengganu | B14: 79022.299 | C14: 31186.999 | D14: 6132.1365 | E14: 1012.36 | G14: - | H14: =Agriculture_FoodSecurity[[#This Row],[2023]]-Agriculture_FoodSecurity[[#This Row],[2022]] -> -47835.3 | I14: =Agriculture_FoodSecurity[[#This Row],[2024]]-Agriculture_FoodSecurity[[#This Row],[2023]] -> -25054.862 | J14: =Agriculture_FoodSecurity[[#This Row],[2025]]-Agriculture_FoodSecurity[[#This Row],[2024]] -> -5119.7765 | L14: - | M14: =IF(OR(Agriculture_FoodSecurity[[#This Row],[2022]]="n.a", Agriculture_FoodSecurity[[#This Row],[2022]]=0, Agriculture_FoodSecurity[[#This Row],[2023]]="n.a"), "-",H14/Agriculture_FoodSecurity[[#This Row],[2022]]) -> -0.60533926 | N14: =IF(OR(Agriculture_FoodSecurity[[#This Row],[2023]]="n.a", Agriculture_FoodSecurity[[#This Row],[2023]]=0, Agriculture_FoodSecurity[[#This Row],[2024]]="n.a"), "-",I14/Agriculture_FoodSecurity[[#This Row],[2023]]) -> -0.80337523 | O14: =IF(OR(Agriculture_FoodSecurity[[#This Row],[2024]]="n.a", Agriculture_FoodSecurity[[#This Row],[2024]]=0, Agriculture_FoodSecurity[[#This Row],[2025]]="n.a"), "-",J14/Agriculture_FoodSecurity[[#This Row],[2024]]) -> -0.83490909
... A16: Sarawak | B16: 98.5 | C16: 98.5 | D16: 453.222 | E16: 94 | G16: - | H16: =Agriculture_FoodSecurity[[#This Row],[2023]]-Agriculture_FoodSecurity[[#This Row],[2022]] -> 0 | I16: =Agriculture_FoodSecurity[[#This Row],[2024]]-Agriculture_FoodSecurity[[#This Row],[2023]] -> 354.722 | J16: =Agriculture_FoodSecurity[[#This Row],[2025]]-Agriculture_FoodSecurity[[#This Row],[2024]] -> -359.222 | L16: - | M16: =IF(OR(Agriculture_FoodSecurity[[#This Row],[2022]]="n.a", Agriculture_FoodSecurity[[#This Row],[2022]]=0, Agriculture_FoodSecurity[[#This Row],[2023]]="n.a"), "-",H16/Agriculture_FoodSecurity[[#This Row],[2022]]) -> 0 | N16: =IF(OR(Agriculture_FoodSecurity[[#This Row],[2023]]="n.a", Agriculture_FoodSecurity[[#This Row],[2023]]=0, Agriculture_FoodSecurity[[#This Row],[2024]]="n.a"), "-",I16/Agriculture_FoodSecurity[[#This Row],[2023]]) -> 3.6012386 | O16: =IF(OR(Agriculture_FoodSecurity[[#This Row],[2024]]="n.a", Agriculture_FoodSecurity[[#This Row],[2024]]=0, Agriculture_FoodSecurity[[#This Row],[2025]]="n.a"), "-",J16/Agriculture_FoodSecurity[[#This Row],[2024]]) -> -0.79259612
A19: State | B19: Plantation and Commodities (RM '000) | G19: Movement | L19: % YoY
A20: Year | B20: 2022 | C20: 2023 | D20: 2024 | E20: 2025 | G20: 2022 | H20: 2023 | I20: 2024 | J20: 2025 | L20: 2022 | M20: 2023 | N20: 2024 | O20: 2025
A21: Malaysia | B21: n.a | C21: 1124.7001 | D21: 22598.02 | E21: 72.148 | G21: - | H21: =IF(OR(Plantation_Commodity[[#This Row],[2023]]="n.a",Plantation_Commodity[[#This Row],[2022]]="n.a"),"-",Plantation_Commodity[[#This Row],[2023]]-Plantation_Commodity[[#This Row],[2022]]) -> - | I21: =IF(OR(Plantation_Commodity[[#This Row],[2024]]="n.a",Plantation_Commodity[[#This Row],[2023]]="n.a"),"-",Plantation_Commodity[[#This Row],[2024]]-Plantation_Commodity[[#This Row],[2023]]) -> 21473.32 | J21: =IF(OR(Plantation_Commodity[[#This Row],[2025]]="n.a",Plantation_Commodity[[#This Row],[2024]]="n.a"),"-",Plantation_Commodity[[#This Row],[2025]]-Plantation_Commodity[[#This Row],[2024]]) -> -22525.872 | L21: - | M21: =IF(OR(Plantation_Commodity[[#This Row],[2022]]="n.a", Plantation_Commodity[[#This Row],[2022]]=0, Plantation_Commodity[[#This Row],[2023]]="n.a"), "-",H21/Plantation_Commodity[[#This Row],[2022]]) -> - | N21: =IF(OR(Plantation_Commodity[[#This Row],[2023]]="n.a", Plantation_Commodity[[#This Row],[2023]]=0, Plantation_Commodity[[#This Row],[2024]]="n.a"), "-",I21/Plantation_Commodity[[#This Row],[2023]]) -> 19.092485 | O21: =IF(OR(Plantation_Commodity[[#This Row],[2024]]="n.a", Plantation_Commodity[[#This Row],[2024]]=0, Plantation_Commodity[[#This Row],[2025]]="n.a"), "-",J21/Plantation_Commodity[[#This Row],[2024]]) -> -0.99680733
A22: Johor | B22: n.a | C22: 42.43 | D22: 3.07512 | E22: 0 | G22: - | H22: =IF(OR(Plantation_Commodity[[#This Row],[2023]]="n.a",Plantation_Commodity[[#This Row],[2022]]="n.a"),"-",Plantation_Commodity[[#This Row],[2023]]-Plantation_Commodity[[#This Row],[2022]]) -> - | I22: =IF(OR(Plantation_Commodity[[#This Row],[2024]]="n.a",Plantation_Commodity[[#This Row],[2023]]="n.a"),"-",Plantation_Commodity[[#This Row],[2024]]-Plantation_Commodity[[#This Row],[2023]]) -> -39.35488 | J22: =IF(OR(Plantation_Commodity[[#This Row],[2025]]="n.a",Plantation_Commodity[[#This Row],[2024]]="n.a"),"-",Plantation_Commodity[[#This Row],[2025]]-Plantation_Commodity[[#This Row],[2024]]) -> -3.07512 | L22: - | M22: =IF(OR(Plantation_Commodity[[#This Row],[2022]]="n.a", Plantation_Commodity[[#This Row],[2022]]=0, Plantation_Commodity[[#This Row],[2023]]="n.a"), "-",H22/Plantation_Commodity[[#This Row],[2022]]) -> - | N22: =IF(OR(Plantation_Commodity[[#This Row],[2023]]="n.a", Plantation_Commodity[[#This Row],[2023]]=0, Plantation_Commodity[[#This Row],[2024]]="n.a"), "-",I22/Plantation_Commodity[[#This Row],[2023]]) -> -0.92752486 | O22: =IF(OR(Plantation_Commodity[[#This Row],[2024]]="n.a", Plantation_Commodity[[#This Row],[2024]]=0, Plantation_Commodity[[#This Row],[2025]]="n.a"), "-",J22/Plantation_Commodity[[#This Row],[2024]]) -> -1
A23: Kedah | B23: n.a | C23: 0 | D23: 0 | E23: 0 | G23: - | H23: =IF(OR(Plantation_Commodity[[#This Row],[2023]]="n.a",Plantation_Commodity[[#This Row],[2022]]="n.a"),"-",Plantation_Commodity[[#This Row],[2023]]-Plantation_Commodity[[#This Row],[2022]]) -> - | I23: =IF(OR(Plantation_Commodity[[#This Row],[2024]]="n.a",Plantation_Commodity[[#This Row],[2023]]="n.a"),"-",Plantation_Commodity[[#This Row],[2024]]-Plantation_Commodity[[#This Row],[2023]]) -> 0 | J23: =IF(OR(Plantation_Commodity[[#This Row],[2025]]="n.a",Plantation_Commodity[[#This Row],[2024]]="n.a"),"-",Plantation_Commodity[[#This Row],[2025]]-Plantation_Commodity[[#This Row],[2024]]) -> 0 | L23: - | M23: =IF(OR(Plantation_Commodity[[#This Row],[2022]]="n.a", Plantation_Commodity[[#This Row],[2022]]=0, Plantation_Commodity[[#This Row],[2023]]="n.a"), "-",H23/Plantation_Commodity[[#This Row],[2022]]) -> - | N23: =IF(OR(Plantation_Commodity[[#This Row],[2023]]="n.a", Plantation_Commodity[[#This Row],[2023]]=0, Plantation_Commodity[[#This Row],[2024]]="n.a"), "-",I23/Plantation_Commodity[[#This Row],[2023]]) -> - | O23: =IF(OR(Plantation_Commodity[[#This Row],[2024]]="n.a", Plantation_Commodity[[#This Row],[2024]]=0, Plantation_Commodity[[#This Row],[2025]]="n.a"), "-",J23/Plantation_Commodity[[#This Row],[2024]]) -> -
A24: Kelantan | B24: n.a | C24: 22.4 | D24: 21344.106 | E24: 0 | G24: - | H24: =IF(OR(Plantation_Commodity[[#This Row],[2023]]="n.a",Plantation_Commodity[[#This Row],[2022]]="n.a"),"-",Plantation_Commodity[[#This Row],[2023]]-Plantation_Commodity[[#This Row],[2022]]) -> - | I24: =IF(OR(Plantation_Commodity[[#This Row],[2024]]="n.a",Plantation_Commodity[[#This Row],[2023]]="n.a"),"-",Plantation_Commodity[[#This Row],[2024]]-Plantation_Commodity[[#This Row],[2023]]) -> 21321.706 | J24: =IF(OR(Plantation_Commodity[[#This Row],[2025]]="n.a",Plantation_Commodity[[#This Row],[2024]]="n.a"),"-",Plantation_Commodity[[#This Row],[2025]]-Plantation_Commodity[[#This Row],[2024]]) -> -21344.106 | L24: - | M24: =IF(OR(Plantation_Commodity[[#This Row],[2022]]="n.a", Plantation_Commodity[[#This Row],[2022]]=0, Plantation_Commodity[[#This Row],[2023]]="n.a"), "-",H24/Plantation_Commodity[[#This Row],[2022]]) -> - | N24: =IF(OR(Plantation_Commodity[[#This Row],[2023]]="n.a", Plantation_Commodity[[#This Row],[2023]]=0, Plantation_Commodity[[#This Row],[2024]]="n.a"), "-",I24/Plantation_Commodity[[#This Row],[2023]]) -> 951.86189 | O24: =IF(OR(Plantation_Commodity[[#This Row],[2024]]="n.a", Plantation_Commodity[[#This Row],[2024]]=0, Plantation_Commodity[[#This Row],[2025]]="n.a"), "-",J24/Plantation_Commodity[[#This Row],[2024]]) -> -1
A25: Melaka | B25: n.a | C25: 1.3 | D25: 0 | E25: 0 | G25: - | H25: =IF(OR(Plantation_Commodity[[#This Row],[2023]]="n.a",Plantation_Commodity[[#This Row],[2022]]="n.a"),"-",Plantation_Commodity[[#This Row],[2023]]-Plantation_Commodity[[#This Row],[2022]]) -> - | I25: =IF(OR(Plantation_Commodity[[#This Row],[2024]]="n.a",Plantation_Commodity[[#This Row],[2023]]="n.a"),"-",Plantation_Commodity[[#This Row],[2024]]-Plantation_Commodity[[#This Row],[2023]]) -> -1.3 | J25: =IF(OR(Plantation_Commodity[[#This Row],[2025]]="n.a",Plantation_Commodity[[#This Row],[2024]]="n.a"),"-",Plantation_Commodity[[#This Row],[2025]]-Plantation_Commodity[[#This Row],[2024]]) -> 0 | L25: - | M25: =IF(OR(Plantation_Commodity[[#This Row],[2022]]="n.a", Plantation_Commodity[[#This Row],[2022]]=0, Plantation_Commodity[[#This Row],[2023]]="n.a"), "-",H25/Plantation_Commodity[[#This Row],[2022]]) -> - | N25: =IF(OR(Plantation_Commodity[[#This Row],[2023]]="n.a", Plantation_Commodity[[#This Row],[2023]]=0, Plantation_Commodity[[#This Row],[2024]]="n.a"), "-",I25/Plantation_Commodity[[#This Row],[2023]]) -> -1 | O25: =IF(OR(Plantation_Commodity[[#This Row],[2024]]="n.a", Plantation_Commodity[[#This Row],[2024]]=0, Plantation_Commodity[[#This Row],[2025]]="n.a"), "-",J25/Plantation_Commodity[[#This Row],[2024]]) -> -
A26: Negeri Sembilan | B26: n.a | C26: 0 | D26: 0 | E26: 0 | G26: - | H26: =IF(OR(Plantation_Commodity[[#This Row],[2023]]="n.a",Plantation_Commodity[[#This Row],[2022]]="n.a"),"-",Plantation_Commodity[[#This Row],[2023]]-Plantation_Commodity[[#This Row],[2022]]) -> - | I26: =IF(OR(Plantation_Commodity[[#This Row],[2024]]="n.a",Plantation_Commodity[[#This Row],[2023]]="n.a"),"-",Plantation_Commodity[[#This Row],[2024]]-Plantation_Commodity[[#This Row],[2023]]) -> 0 | J26: =IF(OR(Plantation_Commodity[[#This Row],[2025]]="n.a",Plantation_Commodity[[#This Row],[2024]]="n.a"),"-",Plantation_Commodity[[#This Row],[2025]]-Plantation_Commodity[[#This Row],[2024]]) -> 0 | L26: - | M26: =IF(OR(Plantation_Commodity[[#This Row],[2022]]="n.a", Plantation_Commodity[[#This Row],[2022]]=0, Plantation_Commodity[[#This Row],[2023]]="n.a"), "-",H26/Plantation_Commodity[[#This Row],[2022]]) -> - | N26: =IF(OR(Plantation_Commodity[[#This Row],[2023]]="n.a", Plantation_Commodity[[#This Row],[2023]]=0, Plantation_Commodity[[#This Row],[2024]]="n.a"), "-",I26/Plantation_Commodity[[#This Row],[2023]]) -> - | O26: =IF(OR(Plantation_Commodity[[#This Row],[2024]]="n.a", Plantation_Commodity[[#This Row],[2024]]=0, Plantation_Commodity[[#This Row],[2025]]="n.a"), "-",J26/Plantation_Commodity[[#This Row],[2024]]) -> -
A27: Pahang | B27: n.a | C27: 675.4 | D27: 0 | E27: 0 | G27: - | H27: =IF(OR(Plantation_Commodity[[#This Row],[2023]]="n.a",Plantation_Commodity[[#This Row],[2022]]="n.a"),"-",Plantation_Commodity[[#This Row],[2023]]-Plantation_Commodity[[#This Row],[2022]]) -> - | I27: =IF(OR(Plantation_Commodity[[#This Row],[2024]]="n.a",Plantation_Commodity[[#This Row],[2023]]="n.a"),"-",Plantation_Commodity[[#This Row],[2024]]-Plantation_Commodity[[#This Row],[2023]]) -> -675.4 | J27: =IF(OR(Plantation_Commodity[[#This Row],[2025]]="n.a",Plantation_Commodity[[#This Row],[2024]]="n.a"),"-",Plantation_Commodity[[#This Row],[2025]]-Plantation_Commodity[[#This Row],[2024]]) -> 0 | L27: - | M27: =IF(OR(Plantation_Commodity[[#This Row],[2022]]="n.a", Plantation_Commodity[[#This Row],[2022]]=0, Plantation_Commodity[[#This Row],[2023]]="n.a"), "-",H27/Plantation_Commodity[[#This Row],[2022]]) -> - | N27: =IF(OR(Plantation_Commodity[[#This Row],[2023]]="n.a", Plantation_Commodity[[#This Row],[2023]]=0, Plantation_Commodity[[#This Row],[2024]]="n.a"), "-",I27/Plantation_Commodity[[#This Row],[2023]]) -> -1 | O27: =IF(OR(Plantation_Commodity[[#This Row],[2024]]="n.a", Plantation_Commodity[[#This Row],[2024]]=0, Plantation_Commodity[[#This Row],[2025]]="n.a"), "-",J27/Plantation_Commodity[[#This Row],[2024]]) -> -
A28: Pulau Pinang | B28: n.a | C28: 0 | D28: 0 | E28: 0 | G28: - | H28: =IF(OR(Plantation_Commodity[[#This Row],[2023]]="n.a",Plantation_Commodity[[#This Row],[2022]]="n.a"),"-",Plantation_Commodity[[#This Row],[2023]]-Plantation_Commodity[[#This Row],[2022]]) -> - | I28: =IF(OR(Plantation_Commodity[[#This Row],[2024]]="n.a",Plantation_Commodity[[#This Row],[2023]]="n.a"),"-",Plantation_Commodity[[#This Row],[2024]]-Plantation_Commodity[[#This Row],[2023]]) -> 0 | J28: =IF(OR(Plantation_Commodity[[#This Row],[2025]]="n.a",Plantation_Commodity[[#This Row],[2024]]="n.a"),"-",Plantation_Commodity[[#This Row],[2025]]-Plantation_Commodity[[#This Row],[2024]]) -> 0 | L28: - | M28: =IF(OR(Plantation_Commodity[[#This Row],[2022]]="n.a", Plantation_Commodity[[#This Row],[2022]]=0, Plantation_Commodity[[#This Row],[2023]]="n.a"), "-",H28/Plantation_Commodity[[#This Row],[2022]]) -> - | N28: =IF(OR(Plantation_Commodity[[#This Row],[2023]]="n.a", Plantation_Commodity[[#This Row],[2023]]=0, Plantation_Commodity[[#This Row],[2024]]="n.a"), "-",I28/Plantation_Commodity[[#This Row],[2023]]) -> - | O28: =IF(OR(Plantation_Commodity[[#This Row],[2024]]="n.a", Plantation_Commodity[[#This Row],[2024]]=0, Plantation_Commodity[[#This Row],[2025]]="n.a"), "-",J28/Plantation_Commodity[[#This Row],[2024]]) -> -
A29: Perak | B29: n.a | C29: 0 | D29: 0 | E29: 0 | G29: - | H29: =IF(OR(Plantation_Commodity[[#This Row],[2023]]="n.a",Plantation_Commodity[[#This Row],[2022]]="n.a"),"-",Plantation_Commodity[[#This Row],[2023]]-Plantation_Commodity[[#This Row],[2022]]) -> - | I29: =IF(OR(Plantation_Commodity[[#This Row],[2024]]="n.a",Plantation_Commodity[[#This Row],[2023]]="n.a"),"-",Plantation_Commodity[[#This Row],[2024]]-Plantation_Commodity[[#This Row],[2023]]) -> 0 | J29: =IF(OR(Plantation_Commodity[[#This Row],[2025]]="n.a",Plantation_Commodity[[#This Row],[2024]]="n.a"),"-",Plantation_Commodity[[#This Row],[2025]]-Plantation_Commodity[[#This Row],[2024]]) -> 0 | L29: - | M29: =IF(OR(Plantation_Commodity[[#This Row],[2022]]="n.a", Plantation_Commodity[[#This Row],[2022]]=0, Plantation_Commodity[[#This Row],[2023]]="n.a"), "-",H29/Plantation_Commodity[[#This Row],[2022]]) -> - | N29: =IF(OR(Plantation_Commodity[[#This Row],[2023]]="n.a", Plantation_Commodity[[#This Row],[2023]]=0, Plantation_Commodity[[#This Row],[2024]]="n.a"), "-",I29/Plantation_Commodity[[#This Row],[2023]]) -> - | O29: =IF(OR(Plantation_Commodity[[#This Row],[2024]]="n.a", Plantation_Commodity[[#This Row],[2024]]=0, Plantation_Commodity[[#This Row],[2025]]="n.a"), "-",J29/Plantation_Commodity[[#This Row],[2024]]) -> -
A30: Perlis | B30: n.a | C30: 0 | D30: 0 | E30: 0 | G30: - | H30: =IF(OR(Plantation_Commodity[[#This Row],[2023]]="n.a",Plantation_Commodity[[#This Row],[2022]]="n.a"),"-",Plantation_Commodity[[#This Row],[2023]]-Plantation_Commodity[[#This Row],[2022]]) -> - | I30: =IF(OR(Plantation_Commodity[[#This Row],[2024]]="n.a",Plantation_Commodity[[#This Row],[2023]]="n.a"),"-",Plantation_Commodity[[#This Row],[2024]]-Plantation_Commodity[[#This Row],[2023]]) -> 0 | J30: =IF(OR(Plantation_Commodity[[#This Row],[2025]]="n.a",Plantation_Commodity[[#This Row],[2024]]="n.a"),"-",Plantation_Commodity[[#This Row],[2025]]-Plantation_Commodity[[#This Row],[2024]]) -> 0 | L30: - | M30: =IF(OR(Plantation_Commodity[[#This Row],[2022]]="n.a", Plantation_Commodity[[#This Row],[2022]]=0, Plantation_Commodity[[#This Row],[2023]]="n.a"), "-",H30/Plantation_Commodity[[#This Row],[2022]]) -> - | N30: =IF(OR(Plantation_Commodity[[#This Row],[2023]]="n.a", Plantation_Commodity[[#This Row],[2023]]=0, Plantation_Commodity[[#This Row],[2024]]="n.a"), "-",I30/Plantation_Commodity[[#This Row],[2023]]) -> - | O30: =IF(OR(Plantation_Commodity[[#This Row],[2024]]="n.a", Plantation_Commodity[[#This Row],[2024]]=0, Plantation_Commodity[[#This Row],[2025]]="n.a"), "-",J30/Plantation_Commodity[[#This Row],[2024]]) -> -
A31: Selangor | B31: n.a | C31: 0 | D31: 17.32266 | E31: 0 | G31: - | H31: =IF(OR(Plantation_Commodity[[#This Row],[2023]]="n.a",Plantation_Commodity[[#This Row],[2022]]="n.a"),"-",Plantation_Commodity[[#This Row],[2023]]-Plantation_Commodity[[#This Row],[2022]]) -> - | I31: =IF(OR(Plantation_Commodity[[#This Row],[2024]]="n.a",Plantation_Commodity[[#This Row],[2023]]="n.a"),"-",Plantation_Commodity[[#This Row],[2024]]-Plantation_Commodity[[#This Row],[2023]]) -> 17.32266 | J31: =IF(OR(Plantation_Commodity[[#This Row],[2025]]="n.a",Plantation_Commodity[[#This Row],[2024]]="n.a"),"-",Plantation_Commodity[[#This Row],[2025]]-Plantation_Commodity[[#This Row],[2024]]) -> -17.32266 | L31: - | M31: =IF(OR(Plantation_Commodity[[#This Row],[2022]]="n.a", Plantation_Commodity[[#This Row],[2022]]=0, Plantation_Commodity[[#This Row],[2023]]="n.a"), "-",H31/Plantation_Commodity[[#This Row],[2022]]) -> - | N31: =IF(OR(Plantation_Commodity[[#This Row],[2023]]="n.a", Plantation_Commodity[[#This Row],[2023]]=0, Plantation_Commodity[[#This Row],[2024]]="n.a"), "-",I31/Plantation_Commodity[[#This Row],[2023]]) -> - | O31: =IF(OR(Plantation_Commodity[[#This Row],[2024]]="n.a", Plantation_Commodity[[#This Row],[2024]]=0, Plantation_Commodity[[#This Row],[2025]]="n.a"), "-",J31/Plantation_Commodity[[#This Row],[2024]]) -> -1
A32: Terengganu | B32: n.a | C32: 94.64011 | D32: 529.08199 | E32: 0 | G32: - | H32: =IF(OR(Plantation_Commodity[[#This Row],[2023]]="n.a",Plantation_Commodity[[#This Row],[2022]]="n.a"),"-",Plantation_Commodity[[#This Row],[2023]]-Plantation_Commodity[[#This Row],[2022]]) -> - | I32: =IF(OR(Plantation_Commodity[[#This Row],[2024]]="n.a",Plantation_Commodity[[#This Row],[2023]]="n.a"),"-",Plantation_Commodity[[#This Row],[2024]]-Plantation_Commodity[[#This Row],[2023]]) -> 434.44188 | J32: =IF(OR(Plantation_Commodity[[#This Row],[2025]]="n.a",Plantation_Commodity[[#This Row],[2024]]="n.a"),"-",Plantation_Commodity[[#This Row],[2025]]-Plantation_Commodity[[#This Row],[2024]]) -> -529.08199 | L32: - | M32: =IF(OR(Plantation_Commodity[[#This Row],[2022]]="n.a", Plantation_Commodity[[#This Row],[2022]]=0, Plantation_Commodity[[#This Row],[2023]]="n.a"), "-",H32/Plantation_Commodity[[#This Row],[2022]]) -> - | N32: =IF(OR(Plantation_Commodity[[#This Row],[2023]]="n.a", Plantation_Commodity[[#This Row],[2023]]=0, Plantation_Commodity[[#This Row],[2024]]="n.a"), "-",I32/Plantation_Commodity[[#This Row],[2023]]) -> 4.5904626 | O32: =IF(OR(Plantation_Commodity[[#This Row],[2024]]="n.a", Plantation_Commodity[[#This Row],[2024]]=0, Plantation_Commodity[[#This Row],[2025]]="n.a"), "-",J32/Plantation_Commodity[[#This Row],[2024]]) -> -1
... A34: Sarawak | B34: n.a | C34: 98.28 | D34: 65.184 | E34: 69 | G34: - | H34: =IF(OR(Plantation_Commodity[[#This Row],[2023]]="n.a",Plantation_Commodity[[#This Row],[2022]]="n.a"),"-",Plantation_Commodity[[#This Row],[2023]]-Plantation_Commodity[[#This Row],[2022]]) -> - | I34: =IF(OR(Plantation_Commodity[[#This Row],[2024]]="n.a",Plantation_Commodity[[#This Row],[2023]]="n.a"),"-",Plantation_Commodity[[#This Row],[2024]]-Plantation_Commodity[[#This Row],[2023]]) -> -33.096 | J34: =IF(OR(Plantation_Commodity[[#This Row],[2025]]="n.a",Plantation_Commodity[[#This Row],[2024]]="n.a"),"-",Plantation_Commodity[[#This Row],[2025]]-Plantation_Commodity[[#This Row],[2024]]) -> 3.816 | L34: - | M34: =IF(OR(Plantation_Commodity[[#This Row],[2022]]="n.a", Plantation_Commodity[[#This Row],[2022]]=0, Plantation_Commodity[[#This Row],[2023]]="n.a"), "-",H34/Plantation_Commodity[[#This Row],[2022]]) -> - | N34: =IF(OR(Plantation_Commodity[[#This Row],[2023]]="n.a", Plantation_Commodity[[#This Row],[2023]]=0, Plantation_Commodity[[#This Row],[2024]]="n.a"), "-",I34/Plantation_Commodity[[#This Row],[2023]]) -> -0.33675214 | O34: =IF(OR(Plantation_Commodity[[#This Row],[2024]]="n.a", Plantation_Commodity[[#This Row],[2024]]=0, Plantation_Commodity[[#This Row],[2025]]="n.a"), "-",J34/Plantation_Commodity[[#This Row],[2024]]) -> 0.058541973
A36: Year | B36: 2022 | C36: 2023 | D36: 2024 | E36: 2025
A37: Malaysia | B37: =IF(OR(B21="n.a",B21=0),NA(),B21) -> #N/A | C37: =IF(OR(C21="n.a",C21=0),NA(),C21) -> 1124.7001 | D37: =IF(OR(D21="n.a",D21=0),NA(),D21) -> 22598.02 | E37: =IF(OR(E21="n.a",E21=0),NA(),E21) -> 72.148
A38: Johor | B38: =IF(OR(B22="n.a",B22=0),NA(),B22) -> #N/A | C38: =IF(OR(C22="n.a",C22=0),NA(),C22) -> 42.43 | D38: =IF(OR(D22="n.a",D22=0),NA(),D22) -> 3.07512 | E38: =IF(OR(E22="n.a",E22=0),NA(),E22) -> #N/A
A39: Kedah | B39: =IF(OR(B23="n.a",B23=0),NA(),B23) -> #N/A | C39: =IF(OR(C23="n.a",C23=0),NA(),C23) -> #N/A | D39: =IF(OR(D23="n.a",D23=0),NA(),D23) -> #N/A | E39: =IF(OR(E23="n.a",E23=0),NA(),E23) -> #N/A
A40: Kelantan | B40: =IF(OR(B24="n.a",B24=0),NA(),B24) -> #N/A | C40: =IF(OR(C24="n.a",C24=0),NA(),C24) -> 22.4 | D40: =IF(OR(D24="n.a",D24=0),NA(),D24) -> 21344.106 | E40: =IF(OR(E24="n.a",E24=0),NA(),E24) -> #N/A
A41: Melaka | B41: =IF(OR(B25="n.a",B25=0),NA(),B25) -> #N/A | C41: =IF(OR(C25="n.a",C25=0),NA(),C25) -> 1.3 | D41: =IF(OR(D25="n.a",D25=0),NA(),D25) -> #N/A | E41: =IF(OR(E25="n.a",E25=0),NA(),E25) -> #N/A
A42: Negeri Sembilan | B42: =IF(OR(B26="n.a",B26=0),NA(),B26) -> #N/A | C42: =IF(OR(C26="n.a",C26=0),NA(),C26) -> #N/A | D42: =IF(OR(D26="n.a",D26=0),NA(),D26) -> #N/A | E42: =IF(OR(E26="n.a",E26=0),NA(),E26) -> #N/A
A43: Pahang | B43: =IF(OR(B27="n.a",B27=0),NA(),B27) -> #N/A | C43: =IF(OR(C27="n.a",C27=0),NA(),C27) -> 675.4 | D43: =IF(OR(D27="n.a",D27=0),NA(),D27) -> #N/A | E43: =IF(OR(E27="n.a",E27=0),NA(),E27) -> #N/A
A44: Pulau Pinang | B44: =IF(OR(B28="n.a",B28=0),NA(),B28) -> #N/A | C44: =IF(OR(C28="n.a",C28=0),NA(),C28) -> #N/A | D44: =IF(OR(D28="n.a",D28=0),NA(),D28) -> #N/A | E44: =IF(OR(E28="n.a",E28=0),NA(),E28) -> #N/A
A45: Perak | B45: =IF(OR(B29="n.a",B29=0),NA(),B29) -> #N/A | C45: =IF(OR(C29="n.a",C29=0),NA(),C29) -> #N/A | D45: =IF(OR(D29="n.a",D29=0),NA(),D29) -> #N/A | E45: =IF(OR(E29="n.a",E29=0),NA(),E29) -> #N/A
...

Sheet Agriculture By Category
A1: Negeri State | B1: (A) Padi Paddy (RM '000) | G1: Movement | L1: % change YoY
A2: Year | B2: 2022 | C2: 2023 | D2: 2024 | E2: 2025 | G2: 2022 | H2: 2023 | I2: 2024 | J2: 2025 | L2: 2022 | M2: 2023 | N2: 2024 | O2: 2025
A3: Malaysia | B3: 81403.955 | C3: 59701.604 | D3: 127848.02 | E3: 0 | G3: - | H3: =IF(OR(Paddy[[#This Row],[2023]]="n.a",Paddy[[#This Row],[2022]]="n.a"),"-",Paddy[[#This Row],[2023]]-Paddy[[#This Row],[2022]]) -> -21702.351 | I3: =IF(OR(Paddy[[#This Row],[2024]]="n.a",Paddy[[#This Row],[2023]]="n.a"),"-",Paddy[[#This Row],[2024]]-Paddy[[#This Row],[2023]]) -> 68146.416 | J3: =IF(OR(Paddy[[#This Row],[2025]]="n.a",Paddy[[#This Row],[2024]]="n.a"),"-",Paddy[[#This Row],[2025]]-Paddy[[#This Row],[2024]]) -> -127848.02 | L3: - | M3: =IF(OR(Paddy[[#This Row],[2022]]="n.a", Paddy[[#This Row],[2022]]=0, Paddy[[#This Row],[2023]]="n.a"), "-",H3/Paddy[[#This Row],[2022]]) -> -0.2666007 | N3: =IF(OR(Paddy[[#This Row],[2023]]="n.a", Paddy[[#This Row],[2023]]=0, Paddy[[#This Row],[2024]]="n.a"), "-",I3/Paddy[[#This Row],[2023]]) -> 1.1414503 | O3: =IF(OR(Paddy[[#This Row],[2024]]="n.a", Paddy[[#This Row],[2024]]=0, Paddy[[#This Row],[2025]]="n.a"), "-",J3/Paddy[[#This Row],[2024]]) -> -1
A4: Johor | B4: 16 | C4: n.a | D4: 0 | E4: 0 | G4: - | H4: =IF(OR(Paddy[[#This Row],[2023]]="n.a",Paddy[[#This Row],[2022]]="n.a"),"-",Paddy[[#This Row],[2023]]-Paddy[[#This Row],[2022]]) -> - | I4: =IF(OR(Paddy[[#This Row],[2024]]="n.a",Paddy[[#This Row],[2023]]="n.a"),"-",Paddy[[#This Row],[2024]]-Paddy[[#This Row],[2023]]) -> - | J4: =IF(OR(Paddy[[#This Row],[2025]]="n.a",Paddy[[#This Row],[2024]]="n.a"),"-",Paddy[[#This Row],[2025]]-Paddy[[#This Row],[2024]]) -> 0 | L4: - | M4: =IF(OR(Paddy[[#This Row],[2022]]="n.a", Paddy[[#This Row],[2022]]=0, Paddy[[#This Row],[2023]]="n.a"), "-",H4/Paddy[[#This Row],[2022]]) -> - | N4: =IF(OR(Paddy[[#This Row],[2023]]="n.a", Paddy[[#This Row],[2023]]=0, Paddy[[#This Row],[2024]]="n.a"), "-",I4/Paddy[[#This Row],[2023]]) -> - | O4: =IF(OR(Paddy[[#This Row],[2024]]="n.a", Paddy[[#This Row],[2024]]=0, Paddy[[#This Row],[2025]]="n.a"), "-",J4/Paddy[[#This Row],[2024]]) -> -
A5: Kedah | B5: 305.9 | C5: n.a | D5: 117473.69 | E5: 0 | G5: - | H5: =IF(OR(Paddy[[#This Row],[2023]]="n.a",Paddy[[#This Row],[2022]]="n.a"),"-",Paddy[[#This Row],[2023]]-Paddy[[#This Row],[2022]]) -> - | I5: =IF(OR(Paddy[[#This Row],[2024]]="n.a",Paddy[[#This Row],[2023]]="n.a"),"-",Paddy[[#This Row],[2024]]-Paddy[[#This Row],[2023]]) -> - | J5: =IF(OR(Paddy[[#This Row],[2025]]="n.a",Paddy[[#This Row],[2024]]="n.a"),"-",Paddy[[#This Row],[2025]]-Paddy[[#This Row],[2024]]) -> -117473.69 | L5: - | M5: =IF(OR(Paddy[[#This Row],[2022]]="n.a", Paddy[[#This Row],[2022]]=0, Paddy[[#This Row],[2023]]="n.a"), "-",H5/Paddy[[#This Row],[2022]]) -> - | N5: =IF(OR(Paddy[[#This Row],[2023]]="n.a", Paddy[[#This Row],[2023]]=0, Paddy[[#This Row],[2024]]="n.a"), "-",I5/Paddy[[#This Row],[2023]]) -> - | O5: =IF(OR(Paddy[[#This Row],[2024]]="n.a", Paddy[[#This Row],[2024]]=0, Paddy[[#This Row],[2025]]="n.a"), "-",J5/Paddy[[#This Row],[2024]]) -> -1
A6: Kelantan | B6: 61654.01 | C6: n.a | D6: 10374.332 | E6: 0 | G6: - | H6: =IF(OR(Paddy[[#This Row],[2023]]="n.a",Paddy[[#This Row],[2022]]="n.a"),"-",Paddy[[#This Row],[2023]]-Paddy[[#This Row],[2022]]) -> - | I6: =IF(OR(Paddy[[#This Row],[2024]]="n.a",Paddy[[#This Row],[2023]]="n.a"),"-",Paddy[[#This Row],[2024]]-Paddy[[#This Row],[2023]]) -> - | J6: =IF(OR(Paddy[[#This Row],[2025]]="n.a",Paddy[[#This Row],[2024]]="n.a"),"-",Paddy[[#This Row],[2025]]-Paddy[[#This Row],[2024]]) -> -10374.332 | L6: - | M6: =IF(OR(Paddy[[#This Row],[2022]]="n.a", Paddy[[#This Row],[2022]]=0, Paddy[[#This Row],[2023]]="n.a"), "-",H6/Paddy[[#This Row],[2022]]) -> - | N6: =IF(OR(Paddy[[#This Row],[2023]]="n.a", Paddy[[#This Row],[2023]]=0, Paddy[[#This Row],[2024]]="n.a"), "-",I6/Paddy[[#This Row],[2023]]) -> - | O6: =IF(OR(Paddy[[#This Row],[2024]]="n.a", Paddy[[#This Row],[2024]]=0, Paddy[[#This Row],[2025]]="n.a"), "-",J6/Paddy[[#This Row],[2024]]) -> -1
A7: Melaka | B7: 0 | C7: n.a | D7: 0 | E7: 0 | G7: - | H7: =IF(OR(Paddy[[#This Row],[2023]]="n.a",Paddy[[#This Row],[2022]]="n.a"),"-",Paddy[[#This Row],[2023]]-Paddy[[#This Row],[2022]]) -> - | I7: =IF(OR(Paddy[[#This Row],[2024]]="n.a",Paddy[[#This Row],[2023]]="n.a"),"-",Paddy[[#This Row],[2024]]-Paddy[[#This Row],[2023]]) -> - | J7: =IF(OR(Paddy[[#This Row],[2025]]="n.a",Paddy[[#This Row],[2024]]="n.a"),"-",Paddy[[#This Row],[2025]]-Paddy[[#This Row],[2024]]) -> 0 | L7: - | M7: =IF(OR(Paddy[[#This Row],[2022]]="n.a", Paddy[[#This Row],[2022]]=0, Paddy[[#This Row],[2023]]="n.a"), "-",H7/Paddy[[#This Row],[2022]]) -> - | N7: =IF(OR(Paddy[[#This Row],[2023]]="n.a", Paddy[[#This Row],[2023]]=0, Paddy[[#This Row],[2024]]="n.a"), "-",I7/Paddy[[#This Row],[2023]]) -> - | O7: =IF(OR(Paddy[[#This Row],[2024]]="n.a", Paddy[[#This Row],[2024]]=0, Paddy[[#This Row],[2025]]="n.a"), "-",J7/Paddy[[#This Row],[2024]]) -> -
A8: Negeri Sembilan | B8: 16.038 | C8: n.a | D8: 0 | E8: 0 | G8: - | H8: =IF(OR(Paddy[[#This Row],[2023]]="n.a",Paddy[[#This Row],[2022]]="n.a"),"-",Paddy[[#This Row],[2023]]-Paddy[[#This Row],[2022]]) -> - | I8: =IF(OR(Paddy[[#This Row],[2024]]="n.a",Paddy[[#This Row],[2023]]="n.a"),"-",Paddy[[#This Row],[2024]]-Paddy[[#This Row],[2023]]) -> - | J8: =IF(OR(Paddy[[#This Row],[2025]]="n.a",Paddy[[#This Row],[2024]]="n.a"),"-",Paddy[[#This Row],[2025]]-Paddy[[#This Row],[2024]]) -> 0 | L8: - | M8: =IF(OR(Paddy[[#This Row],[2022]]="n.a", Paddy[[#This Row],[2022]]=0, Paddy[[#This Row],[2023]]="n.a"), "-",H8/Paddy[[#This Row],[2022]]) -> - | N8: =IF(OR(Paddy[[#This Row],[2023]]="n.a", Paddy[[#This Row],[2023]]=0, Paddy[[#This Row],[2024]]="n.a"), "-",I8/Paddy[[#This Row],[2023]]) -> - | O8: =IF(OR(Paddy[[#This Row],[2024]]="n.a", Paddy[[#This Row],[2024]]=0, Paddy[[#This Row],[2025]]="n.a"), "-",J8/Paddy[[#This Row],[2024]]) -> -
A9: Pahang | B9: 301.5 | C9: n.a | D9: 0 | E9: 0 | G9: - | H9: =IF(OR(Paddy[[#This Row],[2023]]="n.a",Paddy[[#This Row],[2022]]="n.a"),"-",Paddy[[#This Row],[2023]]-Paddy[[#This Row],[2022]]) -> - | I9: =IF(OR(Paddy[[#This Row],[2024]]="n.a",Paddy[[#This Row],[2023]]="n.a"),"-",Paddy[[#This Row],[2024]]-Paddy[[#This Row],[2023]]) -> - | J9: =IF(OR(Paddy[[#This Row],[2025]]="n.a",Paddy[[#This Row],[2024]]="n.a"),"-",Paddy[[#This Row],[2025]]-Paddy[[#This Row],[2024]]) -> 0 | L9: - | M9: =IF(OR(Paddy[[#This Row],[2022]]="n.a", Paddy[[#This Row],[2022]]=0, Paddy[[#This Row],[2023]]="n.a"), "-",H9/Paddy[[#This Row],[2022]]) -> - | N9: =IF(OR(Paddy[[#This Row],[2023]]="n.a", Paddy[[#This Row],[2023]]=0, Paddy[[#This Row],[2024]]="n.a"), "-",I9/Paddy[[#This Row],[2023]]) -> - | O9: =IF(OR(Paddy[[#This Row],[2024]]="n.a", Paddy[[#This Row],[2024]]=0, Paddy[[#This Row],[2025]]="n.a"), "-",J9/Paddy[[#This Row],[2024]]) -> -
A10: Pulau Pinang | B10: 71.848 | C10: n.a | D10: 0 | E10: 0 | G10: - | H10: =IF(OR(Paddy[[#This Row],[2023]]="n.a",Paddy[[#This Row],[2022]]="n.a"),"-",Paddy[[#This Row],[2023]]-Paddy[[#This Row],[2022]]) -> - | I10: =IF(OR(Paddy[[#This Row],[2024]]="n.a",Paddy[[#This Row],[2023]]="n.a"),"-",Paddy[[#This Row],[2024]]-Paddy[[#This Row],[2023]]) -> - | J10: =IF(OR(Paddy[[#This Row],[2025]]="n.a",Paddy[[#This Row],[2024]]="n.a"),"-",Paddy[[#This Row],[2025]]-Paddy[[#This Row],[2024]]) -> 0 | L10: - | M10: =IF(OR(Paddy[[#This Row],[2022]]="n.a", Paddy[[#This Row],[2022]]=0, Paddy[[#This Row],[2023]]="n.a"), "-",H10/Paddy[[#This Row],[2022]]) -> - | N10: =IF(OR(Paddy[[#This Row],[2023]]="n.a", Paddy[[#This Row],[2023]]=0, Paddy[[#This Row],[2024]]="n.a"), "-",I10/Paddy[[#This Row],[2023]]) -> - | O10: =IF(OR(Paddy[[#This Row],[2024]]="n.a", Paddy[[#This Row],[2024]]=0, Paddy[[#This Row],[2025]]="n.a"), "-",J10/Paddy[[#This Row],[2024]]) -> -
A11: Perak | B11: 85.813 | C11: n.a | D11: 0 | E11: 0 | G11: - | H11: =IF(OR(Paddy[[#This Row],[2023]]="n.a",Paddy[[#This Row],[2022]]="n.a"),"-",Paddy[[#This Row],[2023]]-Paddy[[#This Row],[2022]]) -> - | I11: =IF(OR(Paddy[[#This Row],[2024]]="n.a",Paddy[[#This Row],[2023]]="n.a"),"-",Paddy[[#This Row],[2024]]-Paddy[[#This Row],[2023]]) -> - | J11: =IF(OR(Paddy[[#This Row],[2025]]="n.a",Paddy[[#This Row],[2024]]="n.a"),"-",Paddy[[#This Row],[2025]]-Paddy[[#This Row],[2024]]) -> 0 | L11: - | M11: =IF(OR(Paddy[[#This Row],[2022]]="n.a", Paddy[[#This Row],[2022]]=0, Paddy[[#This Row],[2023]]="n.a"), "-",H11/Paddy[[#This Row],[2022]]) -> - | N11: =IF(OR(Paddy[[#This Row],[2023]]="n.a", Paddy[[#This Row],[2023]]=0, Paddy[[#This Row],[2024]]="n.a"), "-",I11/Paddy[[#This Row],[2023]]) -> - | O11: =IF(OR(Paddy[[#This Row],[2024]]="n.a", Paddy[[#This Row],[2024]]=0, Paddy[[#This Row],[2025]]="n.a"), "-",J11/Paddy[[#This Row],[2024]]) -> -
A12: Perlis | B12: 0 | C12: n.a | D12: 0 | E12: 0 | G12: - | H12: =IF(OR(Paddy[[#This Row],[2023]]="n.a",Paddy[[#This Row],[2022]]="n.a"),"-",Paddy[[#This Row],[2023]]-Paddy[[#This Row],[2022]]) -> - | I12: =IF(OR(Paddy[[#This Row],[2024]]="n.a",Paddy[[#This Row],[2023]]="n.a"),"-",Paddy[[#This Row],[2024]]-Paddy[[#This Row],[2023]]) -> - | J12: =IF(OR(Paddy[[#This Row],[2025]]="n.a",Paddy[[#This Row],[2024]]="n.a"),"-",Paddy[[#This Row],[2025]]-Paddy[[#This Row],[2024]]) -> 0 | L12: - | M12: =IF(OR(Paddy[[#This Row],[2022]]="n.a", Paddy[[#This Row],[2022]]=0, Paddy[[#This Row],[2023]]="n.a"), "-",H12/Paddy[[#This Row],[2022]]) -> - | N12: =IF(OR(Paddy[[#This Row],[2023]]="n.a", Paddy[[#This Row],[2023]]=0, Paddy[[#This Row],[2024]]="n.a"), "-",I12/Paddy[[#This Row],[2023]]) -> - | O12: =IF(OR(Paddy[[#This Row],[2024]]="n.a", Paddy[[#This Row],[2024]]=0, Paddy[[#This Row],[2025]]="n.a"), "-",J12/Paddy[[#This Row],[2024]]) -> -
A13: Selangor | B13: 26.604 | C13: n.a | D13: 0 | E13: 0 | G13: - | H13: =IF(OR(Paddy[[#This Row],[2023]]="n.a",Paddy[[#This Row],[2022]]="n.a"),"-",Paddy[[#This Row],[2023]]-Paddy[[#This Row],[2022]]) -> - | I13: =IF(OR(Paddy[[#This Row],[2024]]="n.a",Paddy[[#This Row],[2023]]="n.a"),"-",Paddy[[#This Row],[2024]]-Paddy[[#This Row],[2023]]) -> - | J13: =IF(OR(Paddy[[#This Row],[2025]]="n.a",Paddy[[#This Row],[2024]]="n.a"),"-",Paddy[[#This Row],[2025]]-Paddy[[#This Row],[2024]]) -> 0 | L13: - | M13: =IF(OR(Paddy[[#This Row],[2022]]="n.a", Paddy[[#This Row],[2022]]=0, Paddy[[#This Row],[2023]]="n.a"), "-",H13/Paddy[[#This Row],[2022]]) -> - | N13: =IF(OR(Paddy[[#This Row],[2023]]="n.a", Paddy[[#This Row],[2023]]=0, Paddy[[#This Row],[2024]]="n.a"), "-",I13/Paddy[[#This Row],[2023]]) -> - | O13: =IF(OR(Paddy[[#This Row],[2024]]="n.a", Paddy[[#This Row],[2024]]=0, Paddy[[#This Row],[2025]]="n.a"), "-",J13/Paddy[[#This Row],[2024]]) -> -
A14: Terengganu | B14: 18926.242 | C14: n.a | D14: 0 | E14: 0 | G14: - | H14: =IF(OR(Paddy[[#This Row],[2023]]="n.a",Paddy[[#This Row],[2022]]="n.a"),"-",Paddy[[#This Row],[2023]]-Paddy[[#This Row],[2022]]) -> - | I14: =IF(OR(Paddy[[#This Row],[2024]]="n.a",Paddy[[#This Row],[2023]]="n.a"),"-",Paddy[[#This Row],[2024]]-Paddy[[#This Row],[2023]]) -> - | J14: =IF(OR(Paddy[[#This Row],[2025]]="n.a",Paddy[[#This Row],[2024]]="n.a"),"-",Paddy[[#This Row],[2025]]-Paddy[[#This Row],[2024]]) -> 0 | L14: - | M14: =IF(OR(Paddy[[#This Row],[2022]]="n.a", Paddy[[#This Row],[2022]]=0, Paddy[[#This Row],[2023]]="n.a"), "-",H14/Paddy[[#This Row],[2022]]) -> - | N14: =IF(OR(Paddy[[#This Row],[2023]]="n.a", Paddy[[#This Row],[2023]]=0, Paddy[[#This Row],[2024]]="n.a"), "-",I14/Paddy[[#This Row],[2023]]) -> - | O14: =IF(OR(Paddy[[#This Row],[2024]]="n.a", Paddy[[#This Row],[2024]]=0, Paddy[[#This Row],[2025]]="n.a"), "-",J14/Paddy[[#This Row],[2024]]) -> -
A15: Sabah | B15: 0 | C15: n.a | D15: 0 | E15: 0 | G15: - | H15: =IF(OR(Paddy[[#This Row],[2023]]="n.a",Paddy[[#This Row],[2022]]="n.a"),"-",Paddy[[#This Row],[2023]]-Paddy[[#This Row],[2022]]) -> - | I15: =IF(OR(Paddy[[#This Row],[2024]]="n.a",Paddy[[#This Row],[2023]]="n.a"),"-",Paddy[[#This Row],[2024]]-Paddy[[#This Row],[2023]]) -> - | J15: =IF(OR(Paddy[[#This Row],[2025]]="n.a",Paddy[[#This Row],[2024]]="n.a"),"-",Paddy[[#This Row],[2025]]-Paddy[[#This Row],[2024]]) -> 0 | L15: - | M15: =IF(OR(Paddy[[#This Row],[2022]]="n.a", Paddy[[#This Row],[2022]]=0, Paddy[[#This Row],[2023]]="n.a"), "-",H15/Paddy[[#This Row],[2022]]) -> - | N15: =IF(OR(Paddy[[#This Row],[2023]]="n.a", Paddy[[#This Row],[2023]]=0, Paddy[[#This Row],[2024]]="n.a"), "-",I15/Paddy[[#This Row],[2023]]) -> - | O15: =IF(OR(Paddy[[#This Row],[2024]]="n.a", Paddy[[#This Row],[2024]]=0, Paddy[[#This Row],[2025]]="n.a"), "-",J15/Paddy[[#This Row],[2024]]) -> -
... A17: W.P. Kuala Lumpur | B17: 0 | C17: n.a | D17: 0 | E17: 0 | G17: - | H17: =IF(OR(Paddy[[#This Row],[2023]]="n.a",Paddy[[#This Row],[2022]]="n.a"),"-",Paddy[[#This Row],[2023]]-Paddy[[#This Row],[2022]]) -> - | I17: =IF(OR(Paddy[[#This Row],[2024]]="n.a",Paddy[[#This Row],[2023]]="n.a"),"-",Paddy[[#This Row],[2024]]-Paddy[[#This Row],[2023]]) -> - | J17: =IF(OR(Paddy[[#This Row],[2025]]="n.a",Paddy[[#This Row],[2024]]="n.a"),"-",Paddy[[#This Row],[2025]]-Paddy[[#This Row],[2024]]) -> 0 | L17: - | M17: =IF(OR(Paddy[[#This Row],[2022]]="n.a", Paddy[[#This Row],[2022]]=0, Paddy[[#This Row],[2023]]="n.a"), "-",H17/Paddy[[#This Row],[2022]]) -> - | N17: =IF(OR(Paddy[[#This Row],[2023]]="n.a", Paddy[[#This Row],[2023]]=0, Paddy[[#This Row],[2024]]="n.a"), "-",I17/Paddy[[#This Row],[2023]]) -> - | O17: =IF(OR(Paddy[[#This Row],[2024]]="n.a", Paddy[[#This Row],[2024]]=0, Paddy[[#This Row],[2025]]="n.a"), "-",J17/Paddy[[#This Row],[2024]]) -> -
A19: Negeri State | B19: (B) Tanaman Crops (RM '000) | G19: Movement | L19: % change YoY
A20: Year | B20: 2022 | C20: 2023 | D20: 2024 | E20: 2025 | G20: 2022 | H20: 2023 | I20: 2024 | J20: 2025 | L20: 2022 | M20: 2023 | N20: 2024 | O20: 2025
A21: Malaysia | B21: 33226.753 | C21: 42142.946 | D21: 17227.696 | E21: 14376.019 | G21: - | H21: =IF(OR(Crops[[#This Row],[2023]]="n.a",Crops[[#This Row],[2022]]="n.a"),"-",Crops[[#This Row],[2023]]-Crops[[#This Row],[2022]]) -> 8916.1925 | I21: =IF(OR(Crops[[#This Row],[2024]]="n.a",Crops[[#This Row],[2023]]="n.a"),"-",Crops[[#This Row],[2024]]-Crops[[#This Row],[2023]]) -> -24915.25 | J21: =IF(OR(Crops[[#This Row],[2025]]="n.a",Crops[[#This Row],[2024]]="n.a"),"-",Crops[[#This Row],[2025]]-Crops[[#This Row],[2024]]) -> -2851.6765 | L21: - | M21: =IF(OR(Crops[[#This Row],[2022]]="n.a", Crops[[#This Row],[2022]]=0, Crops[[#This Row],[2023]]="n.a"), "-",H21/Crops[[#This Row],[2022]]) -> 0.26834378 | N21: =IF(OR(Crops[[#This Row],[2023]]="n.a", Crops[[#This Row],[2023]]=0, Crops[[#This Row],[2024]]="n.a"), "-",I21/Crops[[#This Row],[2023]]) -> -0.59120808 | O21: =IF(OR(Crops[[#This Row],[2024]]="n.a", Crops[[#This Row],[2024]]=0, Crops[[#This Row],[2025]]="n.a"), "-",J21/Crops[[#This Row],[2024]]) -> -0.16552861
A22: Johor | B22: 111 | C22: n.a | D22: 724.619 | E22: 719.935 | G22: - | H22: =IF(OR(Crops[[#This Row],[2023]]="n.a",Crops[[#This Row],[2022]]="n.a"),"-",Crops[[#This Row],[2023]]-Crops[[#This Row],[2022]]) -> - | I22: =IF(OR(Crops[[#This Row],[2024]]="n.a",Crops[[#This Row],[2023]]="n.a"),"-",Crops[[#This Row],[2024]]-Crops[[#This Row],[2023]]) -> - | J22: =IF(OR(Crops[[#This Row],[2025]]="n.a",Crops[[#This Row],[2024]]="n.a"),"-",Crops[[#This Row],[2025]]-Crops[[#This Row],[2024]]) -> -4.684 | L22: - | M22: =IF(OR(Crops[[#This Row],[2022]]="n.a", Crops[[#This Row],[2022]]=0, Crops[[#This Row],[2023]]="n.a"), "-",H22/Crops[[#This Row],[2022]]) -> - | N22: =IF(OR(Crops[[#This Row],[2023]]="n.a", Crops[[#This Row],[2023]]=0, Crops[[#This Row],[2024]]="n.a"), "-",I22/Crops[[#This Row],[2023]]) -> - | O22: =IF(OR(Crops[[#This Row],[2024]]="n.a", Crops[[#This Row],[2024]]=0, Crops[[#This Row],[2025]]="n.a"), "-",J22/Crops[[#This Row],[2024]]) -> -0.0064640866
